//finaly clause program error in try and catch code run in always program
//finally clause 
const f = () => {
try {
    let a = 0
    //console.log(program)
    console.log("program  run successefully")
    return
}
catch(error){
    console.log("this an error")
    console.log(p)
}
finally{
    console.log("i am good boy")
    //close the file
    //Exit the Loop
    //Write the log file
}
}
f()
console.log("end")
